{
    DataVersion: 3953,
    size: [6, 4, 5],
    data: [
        {pos: [0, 0, 0], state: "extendedae:assembler_matrix_frame{formed:true,powered:true,shape:block}", nbt: {core: 1b, id: "extendedae:assembler_matrix_frame", proxy: {p: 0}, visual: {}}},
        {pos: [0, 0, 1], state: "extendedae:assembler_matrix_frame{formed:true,powered:true,shape:column_z}", nbt: {core: 0b, id: "extendedae:assembler_matrix_frame", proxy: {p: -1}, visual: {}}},
        {pos: [0, 0, 2], state: "extendedae:assembler_matrix_frame{formed:true,powered:true,shape:column_z}", nbt: {core: 0b, id: "extendedae:assembler_matrix_frame", proxy: {p: -1}, visual: {}}},
        {pos: [0, 0, 3], state: "extendedae:assembler_matrix_frame{formed:true,powered:true,shape:column_z}", nbt: {core: 0b, id: "extendedae:assembler_matrix_frame", proxy: {p: -1}, visual: {}}},
        {pos: [0, 0, 4], state: "extendedae:assembler_matrix_frame{formed:true,powered:true,shape:block}", nbt: {core: 0b, id: "extendedae:assembler_matrix_frame", proxy: {p: -1}, visual: {}}},
        {pos: [1, 0, 0], state: "extendedae:assembler_matrix_frame{formed:true,powered:true,shape:column_x}", nbt: {core: 0b, id: "extendedae:assembler_matrix_frame", proxy: {p: -1}, visual: {}}},
        {pos: [1, 0, 1], state: "extendedae:assembler_matrix_wall{formed:true,powered:true}", nbt: {core: 0b, id: "extendedae:assembler_matrix_wall", proxy: {p: -1}, visual: {}}},
        {pos: [1, 0, 2], state: "extendedae:assembler_matrix_wall{formed:true,powered:true}", nbt: {core: 0b, id: "extendedae:assembler_matrix_wall", proxy: {p: -1}, visual: {}}},
        {pos: [1, 0, 3], state: "extendedae:assembler_matrix_wall{formed:true,powered:true}", nbt: {core: 0b, id: "extendedae:assembler_matrix_wall", proxy: {p: -1}, visual: {}}},
        {pos: [1, 0, 4], state: "extendedae:assembler_matrix_frame{formed:true,powered:true,shape:column_x}", nbt: {core: 0b, id: "extendedae:assembler_matrix_frame", proxy: {p: -1}, visual: {}}},
        {pos: [2, 0, 0], state: "extendedae:assembler_matrix_frame{formed:true,powered:true,shape:column_x}", nbt: {core: 0b, id: "extendedae:assembler_matrix_frame", proxy: {p: -1}, visual: {}}},
        {pos: [2, 0, 1], state: "extendedae:assembler_matrix_wall{formed:true,powered:true}", nbt: {core: 0b, id: "extendedae:assembler_matrix_wall", proxy: {p: -1}, visual: {}}},
        {pos: [2, 0, 2], state: "extendedae:assembler_matrix_wall{formed:true,powered:true}", nbt: {core: 0b, id: "extendedae:assembler_matrix_wall", proxy: {p: -1}, visual: {}}},
        {pos: [2, 0, 3], state: "extendedae:assembler_matrix_wall{formed:true,powered:true}", nbt: {core: 0b, id: "extendedae:assembler_matrix_wall", proxy: {p: -1}, visual: {}}},
        {pos: [2, 0, 4], state: "extendedae:assembler_matrix_frame{formed:true,powered:true,shape:column_x}", nbt: {core: 0b, id: "extendedae:assembler_matrix_frame", proxy: {p: -1}, visual: {}}},
        {pos: [3, 0, 0], state: "extendedae:assembler_matrix_frame{formed:true,powered:true,shape:column_x}", nbt: {core: 0b, id: "extendedae:assembler_matrix_frame", proxy: {p: -1}, visual: {}}},
        {pos: [3, 0, 1], state: "extendedae:assembler_matrix_wall{formed:true,powered:true}", nbt: {core: 0b, id: "extendedae:assembler_matrix_wall", proxy: {p: -1}, visual: {}}},
        {pos: [3, 0, 2], state: "extendedae:assembler_matrix_wall{formed:true,powered:true}", nbt: {core: 0b, id: "extendedae:assembler_matrix_wall", proxy: {p: -1}, visual: {}}},
        {pos: [3, 0, 3], state: "extendedae:assembler_matrix_wall{formed:true,powered:true}", nbt: {core: 0b, id: "extendedae:assembler_matrix_wall", proxy: {p: -1}, visual: {}}},
        {pos: [3, 0, 4], state: "extendedae:assembler_matrix_frame{formed:true,powered:true,shape:column_x}", nbt: {core: 0b, id: "extendedae:assembler_matrix_frame", proxy: {p: -1}, visual: {}}},
        {pos: [4, 0, 0], state: "extendedae:assembler_matrix_frame{formed:true,powered:true,shape:column_x}", nbt: {core: 0b, id: "extendedae:assembler_matrix_frame", proxy: {p: -1}, visual: {}}},
        {pos: [4, 0, 1], state: "extendedae:assembler_matrix_wall{formed:true,powered:true}", nbt: {core: 0b, id: "extendedae:assembler_matrix_wall", proxy: {p: -1}, visual: {}}},
        {pos: [4, 0, 2], state: "extendedae:assembler_matrix_wall{formed:true,powered:true}", nbt: {core: 0b, id: "extendedae:assembler_matrix_wall", proxy: {p: -1}, visual: {}}},
        {pos: [4, 0, 3], state: "extendedae:assembler_matrix_wall{formed:true,powered:true}", nbt: {core: 0b, id: "extendedae:assembler_matrix_wall", proxy: {p: -1}, visual: {}}},
        {pos: [4, 0, 4], state: "extendedae:assembler_matrix_frame{formed:true,powered:true,shape:column_x}", nbt: {core: 0b, id: "extendedae:assembler_matrix_frame", proxy: {p: -1}, visual: {}}},
        {pos: [5, 0, 0], state: "extendedae:assembler_matrix_frame{formed:true,powered:true,shape:block}", nbt: {core: 0b, id: "extendedae:assembler_matrix_frame", proxy: {p: -1}, visual: {}}},
        {pos: [5, 0, 1], state: "extendedae:assembler_matrix_frame{formed:true,powered:true,shape:column_z}", nbt: {core: 0b, id: "extendedae:assembler_matrix_frame", proxy: {p: -1}, visual: {}}},
        {pos: [5, 0, 2], state: "extendedae:assembler_matrix_frame{formed:true,powered:true,shape:column_z}", nbt: {core: 0b, id: "extendedae:assembler_matrix_frame", proxy: {p: -1}, visual: {}}},
        {pos: [5, 0, 3], state: "extendedae:assembler_matrix_frame{formed:true,powered:true,shape:column_z}", nbt: {core: 0b, id: "extendedae:assembler_matrix_frame", proxy: {p: -1}, visual: {}}},
        {pos: [5, 0, 4], state: "extendedae:assembler_matrix_frame{formed:true,powered:true,shape:block}", nbt: {core: 0b, id: "extendedae:assembler_matrix_frame", proxy: {p: -1}, visual: {}}},
        {pos: [0, 1, 0], state: "extendedae:assembler_matrix_frame{formed:true,powered:true,shape:column_y}", nbt: {core: 0b, id: "extendedae:assembler_matrix_frame", proxy: {p: 0}, visual: {}}},
        {pos: [0, 1, 1], state: "extendedae:assembler_matrix_wall{formed:true,powered:true}", nbt: {core: 0b, id: "extendedae:assembler_matrix_wall", proxy: {p: -1}, visual: {}}},
        {pos: [0, 1, 2], state: "extendedae:assembler_matrix_wall{formed:true,powered:true}", nbt: {core: 0b, id: "extendedae:assembler_matrix_wall", proxy: {p: -1}, visual: {}}},
        {pos: [0, 1, 3], state: "extendedae:assembler_matrix_wall{formed:true,powered:true}", nbt: {core: 0b, id: "extendedae:assembler_matrix_wall", proxy: {p: -1}, visual: {}}},
        {pos: [0, 1, 4], state: "extendedae:assembler_matrix_frame{formed:true,powered:true,shape:column_y}", nbt: {core: 0b, id: "extendedae:assembler_matrix_frame", proxy: {p: -1}, visual: {}}},
        {pos: [1, 1, 0], state: "extendedae:assembler_matrix_wall{formed:true,powered:true}", nbt: {core: 0b, id: "extendedae:assembler_matrix_wall", proxy: {p: -1}, visual: {}}},
        {pos: [1, 1, 1], state: "extendedae:assembler_matrix_pattern{formed:true,powered:true}", nbt: {core: 0b, id: "extendedae:assembler_matrix_pattern", locate_id: 655658709, proxy: {p: 0}, visual: {}}},
        {pos: [1, 1, 2], state: "extendedae:assembler_matrix_pattern{formed:true,powered:true}", nbt: {core: 0b, id: "extendedae:assembler_matrix_pattern", locate_id: -218163096, pattern: [{Slot: 3, components: {"ae2:encoded_crafting_pattern": {canSubstitute: 1b, canSubstituteFluids: 1b, inputs: [{count: 1, id: "minecraft:birch_planks"}, {count: 1, id: "minecraft:birch_planks"}, {}, {count: 1, id: "minecraft:birch_planks"}, {count: 1, id: "minecraft:birch_planks"}, {}, {}, {}, {}], recipeId: "minecraft:crafting_table", result: {count: 1, id: "minecraft:crafting_table"}}}, count: 1, id: "ae2:crafting_pattern"}], proxy: {p: 0}, visual: {}}},
        {pos: [1, 1, 3], state: "extendedae:assembler_matrix_pattern{formed:true,powered:true}", nbt: {core: 0b, id: "extendedae:assembler_matrix_pattern", locate_id: 1569505305, proxy: {p: 0}, visual: {}}},
        {pos: [1, 1, 4], state: "extendedae:assembler_matrix_wall{formed:true,powered:true}", nbt: {core: 0b, id: "extendedae:assembler_matrix_wall", proxy: {p: -1}, visual: {}}},
        {pos: [2, 1, 0], state: "extendedae:assembler_matrix_wall{formed:true,powered:true}", nbt: {core: 0b, id: "extendedae:assembler_matrix_wall", proxy: {p: -1}, visual: {}}},
        {pos: [2, 1, 1], state: "extendedae:assembler_matrix_pattern{formed:true,powered:true}", nbt: {core: 0b, id: "extendedae:assembler_matrix_pattern", locate_id: -1392195008, proxy: {p: -1}, visual: {}}},
        {pos: [2, 1, 2], state: "extendedae:assembler_matrix_pattern{formed:true,powered:true}", nbt: {core: 0b, id: "extendedae:assembler_matrix_pattern", locate_id: 1985181215, proxy: {p: -1}, visual: {}}},
        {pos: [2, 1, 3], state: "extendedae:assembler_matrix_pattern{formed:true,powered:true}", nbt: {core: 0b, id: "extendedae:assembler_matrix_pattern", locate_id: 1763323109, proxy: {p: -1}, visual: {}}},
        {pos: [2, 1, 4], state: "extendedae:assembler_matrix_wall{formed:true,powered:true}", nbt: {core: 0b, id: "extendedae:assembler_matrix_wall", proxy: {p: -1}, visual: {}}},
        {pos: [3, 1, 0], state: "extendedae:assembler_matrix_wall{formed:true,powered:true}", nbt: {core: 0b, id: "extendedae:assembler_matrix_wall", proxy: {p: -1}, visual: {}}},
        {pos: [3, 1, 1], state: "extendedae:assembler_matrix_pattern{formed:true,powered:true}", nbt: {core: 0b, id: "extendedae:assembler_matrix_pattern", locate_id: 658053616, proxy: {p: -1}, visual: {}}},
        {pos: [3, 1, 2], state: "extendedae:assembler_matrix_pattern{formed:true,powered:true}", nbt: {core: 0b, id: "extendedae:assembler_matrix_pattern", locate_id: -931396487, proxy: {p: -1}, visual: {}}},
        {pos: [3, 1, 3], state: "extendedae:assembler_matrix_pattern{formed:true,powered:true}", nbt: {core: 0b, id: "extendedae:assembler_matrix_pattern", locate_id: -1843791140, proxy: {p: -1}, visual: {}}},
        {pos: [3, 1, 4], state: "extendedae:assembler_matrix_wall{formed:true,powered:true}", nbt: {core: 0b, id: "extendedae:assembler_matrix_wall", proxy: {p: -1}, visual: {}}},
        {pos: [4, 1, 0], state: "extendedae:assembler_matrix_wall{formed:true,powered:true}", nbt: {core: 0b, id: "extendedae:assembler_matrix_wall", proxy: {p: -1}, visual: {}}},
        {pos: [4, 1, 1], state: "extendedae:assembler_matrix_pattern{formed:true,powered:true}", nbt: {core: 0b, id: "extendedae:assembler_matrix_pattern", locate_id: -925107138, proxy: {p: -1}, visual: {}}},
        {pos: [4, 1, 2], state: "extendedae:assembler_matrix_pattern{formed:true,powered:true}", nbt: {core: 0b, id: "extendedae:assembler_matrix_pattern", locate_id: 1421715594, proxy: {p: -1}, visual: {}}},
        {pos: [4, 1, 3], state: "extendedae:assembler_matrix_pattern{formed:true,powered:true}", nbt: {core: 0b, id: "extendedae:assembler_matrix_pattern", locate_id: 335757549, pattern: [{Slot: 0, components: {"ae2:encoded_crafting_pattern": {canSubstitute: 1b, canSubstituteFluids: 1b, inputs: [{count: 1, id: "minecraft:birch_planks"}, {count: 1, id: "minecraft:birch_planks"}, {}, {count: 1, id: "minecraft:birch_planks"}, {count: 1, id: "minecraft:birch_planks"}, {}, {}, {}, {}], recipeId: "minecraft:crafting_table", result: {count: 1, id: "minecraft:crafting_table"}}}, count: 1, id: "ae2:crafting_pattern"}, {Slot: 10, components: {"ae2:encoded_crafting_pattern": {canSubstitute: 1b, canSubstituteFluids: 1b, inputs: [{count: 1, id: "minecraft:birch_planks"}, {count: 1, id: "minecraft:birch_planks"}, {}, {count: 1, id: "minecraft:birch_planks"}, {count: 1, id: "minecraft:birch_planks"}, {}, {}, {}, {}], recipeId: "minecraft:crafting_table", result: {count: 1, id: "minecraft:crafting_table"}}}, count: 1, id: "ae2:crafting_pattern"}, {Slot: 22, components: {"ae2:encoded_crafting_pattern": {canSubstitute: 1b, canSubstituteFluids: 1b, inputs: [{count: 1, id: "minecraft:birch_planks"}, {count: 1, id: "minecraft:birch_planks"}, {}, {count: 1, id: "minecraft:birch_planks"}, {count: 1, id: "minecraft:birch_planks"}, {}, {}, {}, {}], recipeId: "minecraft:crafting_table", result: {count: 1, id: "minecraft:crafting_table"}}}, count: 1, id: "ae2:crafting_pattern"}, {Slot: 30, components: {"ae2:encoded_crafting_pattern": {canSubstitute: 1b, canSubstituteFluids: 1b, inputs: [{count: 1, id: "minecraft:birch_planks"}, {count: 1, id: "minecraft:birch_planks"}, {}, {count: 1, id: "minecraft:birch_planks"}, {count: 1, id: "minecraft:birch_planks"}, {}, {}, {}, {}], recipeId: "minecraft:crafting_table", result: {count: 1, id: "minecraft:crafting_table"}}}, count: 1, id: "ae2:crafting_pattern"}], proxy: {p: -1}, visual: {}}},
        {pos: [4, 1, 4], state: "extendedae:assembler_matrix_wall{formed:true,powered:true}", nbt: {core: 0b, id: "extendedae:assembler_matrix_wall", proxy: {p: -1}, visual: {}}},
        {pos: [5, 1, 0], state: "extendedae:assembler_matrix_frame{formed:true,powered:true,shape:column_y}", nbt: {core: 0b, id: "extendedae:assembler_matrix_frame", proxy: {p: -1}, visual: {}}},
        {pos: [5, 1, 1], state: "extendedae:assembler_matrix_wall{formed:true,powered:true}", nbt: {core: 0b, id: "extendedae:assembler_matrix_wall", proxy: {p: -1}, visual: {}}},
        {pos: [5, 1, 2], state: "extendedae:assembler_matrix_wall{formed:true,powered:true}", nbt: {core: 0b, id: "extendedae:assembler_matrix_wall", proxy: {p: -1}, visual: {}}},
        {pos: [5, 1, 3], state: "extendedae:assembler_matrix_wall{formed:true,powered:true}", nbt: {core: 0b, id: "extendedae:assembler_matrix_wall", proxy: {p: -1}, visual: {}}},
        {pos: [5, 1, 4], state: "extendedae:assembler_matrix_frame{formed:true,powered:true,shape:column_y}", nbt: {core: 0b, id: "extendedae:assembler_matrix_frame", proxy: {p: -1}, visual: {}}},
        {pos: [0, 2, 0], state: "extendedae:assembler_matrix_frame{formed:true,powered:true,shape:column_y}", nbt: {core: 0b, id: "extendedae:assembler_matrix_frame", proxy: {p: 0}, visual: {}}},
        {pos: [0, 2, 1], state: "extendedae:assembler_matrix_wall{formed:true,powered:true}", nbt: {core: 0b, id: "extendedae:assembler_matrix_wall", proxy: {p: 0}, visual: {}}},
        {pos: [0, 2, 2], state: "extendedae:assembler_matrix_wall{formed:true,powered:true}", nbt: {core: 0b, id: "extendedae:assembler_matrix_wall", proxy: {p: -1}, visual: {}}},
        {pos: [0, 2, 3], state: "extendedae:assembler_matrix_wall{formed:true,powered:true}", nbt: {core: 0b, id: "extendedae:assembler_matrix_wall", proxy: {p: -1}, visual: {}}},
        {pos: [0, 2, 4], state: "extendedae:assembler_matrix_frame{formed:true,powered:true,shape:column_y}", nbt: {core: 0b, id: "extendedae:assembler_matrix_frame", proxy: {p: -1}, visual: {}}},
        {pos: [1, 2, 0], state: "extendedae:assembler_matrix_wall{formed:true,powered:true}", nbt: {core: 0b, id: "extendedae:assembler_matrix_wall", proxy: {p: -1}, visual: {}}},
        {pos: [1, 2, 1], state: "extendedae:assembler_matrix_pattern{formed:true,powered:true}", nbt: {core: 0b, id: "extendedae:assembler_matrix_pattern", locate_id: 543801052, proxy: {p: 0}, visual: {}}},
        {pos: [1, 2, 2], state: "extendedae:assembler_matrix_pattern{formed:true,powered:true}", nbt: {core: 0b, id: "extendedae:assembler_matrix_pattern", locate_id: 131687045, proxy: {p: 0}, visual: {}}},
        {pos: [1, 2, 3], state: "extendedae:assembler_matrix_speed{formed:true,powered:true}", nbt: {core: 0b, id: "extendedae:assembler_matrix_speed", proxy: {p: 0}, visual: {}}},
        {pos: [1, 2, 4], state: "extendedae:assembler_matrix_wall{formed:true,powered:true}", nbt: {core: 0b, id: "extendedae:assembler_matrix_wall", proxy: {p: -1}, visual: {}}},
        {pos: [2, 2, 0], state: "extendedae:assembler_matrix_wall{formed:true,powered:true}", nbt: {core: 0b, id: "extendedae:assembler_matrix_wall", proxy: {p: -1}, visual: {}}},
        {pos: [2, 2, 1], state: "extendedae:assembler_matrix_pattern{formed:true,powered:true}", nbt: {core: 0b, id: "extendedae:assembler_matrix_pattern", locate_id: 579579825, proxy: {p: 0}, visual: {}}},
        {pos: [2, 2, 2], state: "extendedae:assembler_matrix_pattern{formed:true,powered:true}", nbt: {core: 0b, id: "extendedae:assembler_matrix_pattern", locate_id: 111635239, proxy: {p: 0}, visual: {}}},
        {pos: [2, 2, 3], state: "extendedae:assembler_matrix_speed{formed:true,powered:true}", nbt: {core: 0b, id: "extendedae:assembler_matrix_speed", proxy: {p: 0}, visual: {}}},
        {pos: [2, 2, 4], state: "extendedae:assembler_matrix_wall{formed:true,powered:true}", nbt: {core: 0b, id: "extendedae:assembler_matrix_wall", proxy: {p: -1}, visual: {}}},
        {pos: [3, 2, 0], state: "extendedae:assembler_matrix_wall{formed:true,powered:true}", nbt: {core: 0b, id: "extendedae:assembler_matrix_wall", proxy: {p: -1}, visual: {}}},
        {pos: [3, 2, 1], state: "extendedae:assembler_matrix_speed{formed:true,powered:true}", nbt: {core: 0b, id: "extendedae:assembler_matrix_speed", proxy: {p: 0}, visual: {}}},
        {pos: [3, 2, 2], state: "extendedae:assembler_matrix_speed{formed:true,powered:true}", nbt: {core: 0b, id: "extendedae:assembler_matrix_speed", proxy: {p: 0}, visual: {}}},
        {pos: [3, 2, 3], state: "extendedae:assembler_matrix_speed{formed:true,powered:true}", nbt: {core: 0b, id: "extendedae:assembler_matrix_speed", proxy: {p: 0}, visual: {}}},
        {pos: [3, 2, 4], state: "extendedae:assembler_matrix_wall{formed:true,powered:true}", nbt: {core: 0b, id: "extendedae:assembler_matrix_wall", proxy: {p: -1}, visual: {}}},
        {pos: [4, 2, 0], state: "extendedae:assembler_matrix_wall{formed:true,powered:true}", nbt: {core: 0b, id: "extendedae:assembler_matrix_wall", proxy: {p: -1}, visual: {}}},
        {pos: [4, 2, 1], state: "extendedae:assembler_matrix_crafter{formed:true,powered:true}", nbt: {"#ct0": {}, "#ct1": {}, "#ct2": {}, "#ct3": {}, "#ct4": {}, "#ct5": {}, "#ct6": {}, "#ct7": {}, core: 0b, id: "extendedae:assembler_matrix_crafter", inv: {item0: {}, item1: {}, item10: {}, item11: {}, item12: {}, item13: {}, item14: {}, item15: {}, item16: {}, item17: {}, item18: {}, item19: {}, item2: {}, item20: {}, item21: {}, item22: {}, item23: {}, item24: {}, item25: {}, item26: {}, item27: {}, item28: {}, item29: {}, item3: {}, item30: {}, item31: {}, item32: {}, item33: {}, item34: {}, item35: {}, item36: {}, item37: {}, item38: {}, item39: {}, item4: {}, item40: {}, item41: {}, item42: {}, item43: {}, item44: {}, item45: {}, item46: {}, item47: {}, item48: {}, item49: {}, item5: {}, item50: {}, item51: {}, item52: {}, item53: {}, item54: {}, item55: {}, item56: {}, item57: {}, item58: {}, item59: {}, item6: {}, item60: {}, item61: {}, item62: {}, item63: {}, item64: {}, item65: {}, item66: {}, item67: {}, item68: {}, item69: {}, item7: {}, item70: {}, item71: {}, item72: {}, item73: {}, item74: {}, item75: {}, item76: {}, item77: {}, item78: {}, item79: {}, item8: {}, item9: {}}, proxy: {p: 0}, visual: {}}},
        {pos: [4, 2, 2], state: "extendedae:assembler_matrix_crafter{formed:true,powered:true}", nbt: {"#ct0": {}, "#ct1": {}, "#ct2": {}, "#ct3": {}, "#ct4": {}, "#ct5": {}, "#ct6": {}, "#ct7": {}, core: 0b, id: "extendedae:assembler_matrix_crafter", inv: {item0: {}, item1: {}, item10: {}, item11: {}, item12: {}, item13: {}, item14: {}, item15: {}, item16: {}, item17: {}, item18: {}, item19: {}, item2: {}, item20: {}, item21: {}, item22: {}, item23: {}, item24: {}, item25: {}, item26: {}, item27: {}, item28: {}, item29: {}, item3: {}, item30: {}, item31: {}, item32: {}, item33: {}, item34: {}, item35: {}, item36: {}, item37: {}, item38: {}, item39: {}, item4: {}, item40: {}, item41: {}, item42: {}, item43: {}, item44: {}, item45: {}, item46: {}, item47: {}, item48: {}, item49: {}, item5: {}, item50: {}, item51: {}, item52: {}, item53: {}, item54: {}, item55: {}, item56: {}, item57: {}, item58: {}, item59: {}, item6: {}, item60: {}, item61: {}, item62: {}, item63: {}, item64: {}, item65: {}, item66: {}, item67: {}, item68: {}, item69: {}, item7: {}, item70: {}, item71: {}, item72: {}, item73: {}, item74: {}, item75: {}, item76: {}, item77: {}, item78: {}, item79: {}, item8: {}, item9: {}}, proxy: {p: 0}, visual: {}}},
        {pos: [4, 2, 3], state: "extendedae:assembler_matrix_crafter{formed:true,powered:true}", nbt: {"#ct0": {}, "#ct1": {}, "#ct2": {}, "#ct3": {}, "#ct4": {}, "#ct5": {}, "#ct6": {}, "#ct7": {}, core: 0b, id: "extendedae:assembler_matrix_crafter", inv: {item0: {}, item1: {}, item10: {}, item11: {}, item12: {}, item13: {}, item14: {}, item15: {}, item16: {}, item17: {}, item18: {}, item19: {}, item2: {}, item20: {}, item21: {}, item22: {}, item23: {}, item24: {}, item25: {}, item26: {}, item27: {}, item28: {}, item29: {}, item3: {}, item30: {}, item31: {}, item32: {}, item33: {}, item34: {}, item35: {}, item36: {}, item37: {}, item38: {}, item39: {}, item4: {}, item40: {}, item41: {}, item42: {}, item43: {}, item44: {}, item45: {}, item46: {}, item47: {}, item48: {}, item49: {}, item5: {}, item50: {}, item51: {}, item52: {}, item53: {}, item54: {}, item55: {}, item56: {}, item57: {}, item58: {}, item59: {}, item6: {}, item60: {}, item61: {}, item62: {}, item63: {}, item64: {}, item65: {}, item66: {}, item67: {}, item68: {}, item69: {}, item7: {}, item70: {}, item71: {}, item72: {}, item73: {}, item74: {}, item75: {}, item76: {}, item77: {}, item78: {}, item79: {}, item8: {}, item9: {}}, proxy: {p: 0}, visual: {}}},
        {pos: [4, 2, 4], state: "extendedae:assembler_matrix_wall{formed:true,powered:true}", nbt: {core: 0b, id: "extendedae:assembler_matrix_wall", proxy: {p: -1}, visual: {}}},
        {pos: [5, 2, 0], state: "extendedae:assembler_matrix_frame{formed:true,powered:true,shape:column_y}", nbt: {core: 0b, id: "extendedae:assembler_matrix_frame", proxy: {p: -1}, visual: {}}},
        {pos: [5, 2, 1], state: "extendedae:assembler_matrix_wall{formed:true,powered:true}", nbt: {core: 0b, id: "extendedae:assembler_matrix_wall", proxy: {p: -1}, visual: {}}},
        {pos: [5, 2, 2], state: "extendedae:assembler_matrix_wall{formed:true,powered:true}", nbt: {core: 0b, id: "extendedae:assembler_matrix_wall", proxy: {p: -1}, visual: {}}},
        {pos: [5, 2, 3], state: "extendedae:assembler_matrix_wall{formed:true,powered:true}", nbt: {core: 0b, id: "extendedae:assembler_matrix_wall", proxy: {p: -1}, visual: {}}},
        {pos: [5, 2, 4], state: "extendedae:assembler_matrix_frame{formed:true,powered:true,shape:column_y}", nbt: {core: 0b, id: "extendedae:assembler_matrix_frame", proxy: {p: -1}, visual: {}}},
        {pos: [0, 3, 0], state: "extendedae:assembler_matrix_frame{formed:true,powered:true,shape:block}", nbt: {core: 0b, id: "extendedae:assembler_matrix_frame", proxy: {p: 0}, visual: {}}},
        {pos: [0, 3, 1], state: "extendedae:assembler_matrix_frame{formed:true,powered:true,shape:column_z}", nbt: {core: 0b, id: "extendedae:assembler_matrix_frame", proxy: {p: -1}, visual: {}}},
        {pos: [0, 3, 2], state: "extendedae:assembler_matrix_frame{formed:true,powered:true,shape:column_z}", nbt: {core: 0b, id: "extendedae:assembler_matrix_frame", proxy: {p: -1}, visual: {}}},
        {pos: [0, 3, 3], state: "extendedae:assembler_matrix_frame{formed:true,powered:true,shape:column_z}", nbt: {core: 0b, id: "extendedae:assembler_matrix_frame", proxy: {p: -1}, visual: {}}},
        {pos: [0, 3, 4], state: "extendedae:assembler_matrix_frame{formed:true,powered:true,shape:block}", nbt: {core: 0b, id: "extendedae:assembler_matrix_frame", proxy: {p: 0}, visual: {}}},
        {pos: [1, 3, 0], state: "extendedae:assembler_matrix_frame{formed:true,powered:true,shape:column_x}", nbt: {core: 0b, id: "extendedae:assembler_matrix_frame", proxy: {p: 0}, visual: {}}},
        {pos: [1, 3, 1], state: "extendedae:assembler_matrix_wall{formed:true,powered:true}", nbt: {core: 0b, id: "extendedae:assembler_matrix_wall", proxy: {p: 0}, visual: {}}},
        {pos: [1, 3, 2], state: "extendedae:assembler_matrix_wall{formed:true,powered:true}", nbt: {core: 0b, id: "extendedae:assembler_matrix_wall", proxy: {p: 0}, visual: {}}},
        {pos: [1, 3, 3], state: "extendedae:assembler_matrix_wall{formed:true,powered:true}", nbt: {core: 0b, id: "extendedae:assembler_matrix_wall", proxy: {p: 0}, visual: {}}},
        {pos: [1, 3, 4], state: "extendedae:assembler_matrix_frame{formed:true,powered:true,shape:column_x}", nbt: {core: 0b, id: "extendedae:assembler_matrix_frame", proxy: {p: 0}, visual: {}}},
        {pos: [2, 3, 0], state: "extendedae:assembler_matrix_frame{formed:true,powered:true,shape:column_x}", nbt: {core: 0b, id: "extendedae:assembler_matrix_frame", proxy: {p: -1}, visual: {}}},
        {pos: [2, 3, 1], state: "extendedae:assembler_matrix_wall{formed:true,powered:true}", nbt: {core: 0b, id: "extendedae:assembler_matrix_wall", proxy: {p: 0}, visual: {}}},
        {pos: [2, 3, 2], state: "extendedae:assembler_matrix_wall{formed:true,powered:true}", nbt: {core: 0b, id: "extendedae:assembler_matrix_wall", proxy: {p: 0}, visual: {}}},
        {pos: [2, 3, 3], state: "extendedae:assembler_matrix_wall{formed:true,powered:true}", nbt: {core: 0b, id: "extendedae:assembler_matrix_wall", proxy: {p: 0}, visual: {}}},
        {pos: [2, 3, 4], state: "extendedae:assembler_matrix_frame{formed:true,powered:true,shape:column_x}", nbt: {core: 0b, id: "extendedae:assembler_matrix_frame", proxy: {p: 0}, visual: {}}},
        {pos: [3, 3, 0], state: "extendedae:assembler_matrix_frame{formed:true,powered:true,shape:column_x}", nbt: {core: 0b, id: "extendedae:assembler_matrix_frame", proxy: {p: -1}, visual: {}}},
        {pos: [3, 3, 1], state: "extendedae:assembler_matrix_wall{formed:true,powered:true}", nbt: {core: 0b, id: "extendedae:assembler_matrix_wall", proxy: {p: 0}, visual: {}}},
        {pos: [3, 3, 2], state: "extendedae:assembler_matrix_wall{formed:true,powered:true}", nbt: {core: 0b, id: "extendedae:assembler_matrix_wall", proxy: {p: 0}, visual: {}}},
        {pos: [3, 3, 3], state: "extendedae:assembler_matrix_wall{formed:true,powered:true}", nbt: {core: 0b, id: "extendedae:assembler_matrix_wall", proxy: {p: 0}, visual: {}}},
        {pos: [3, 3, 4], state: "extendedae:assembler_matrix_frame{formed:true,powered:true,shape:column_x}", nbt: {core: 0b, id: "extendedae:assembler_matrix_frame", proxy: {p: 0}, visual: {}}},
        {pos: [4, 3, 0], state: "extendedae:assembler_matrix_frame{formed:true,powered:true,shape:column_x}", nbt: {core: 0b, id: "extendedae:assembler_matrix_frame", proxy: {p: -1}, visual: {}}},
        {pos: [4, 3, 1], state: "extendedae:assembler_matrix_wall{formed:true,powered:true}", nbt: {core: 0b, id: "extendedae:assembler_matrix_wall", proxy: {p: 0}, visual: {}}},
        {pos: [4, 3, 2], state: "extendedae:assembler_matrix_wall{formed:true,powered:true}", nbt: {core: 0b, id: "extendedae:assembler_matrix_wall", proxy: {p: 0}, visual: {}}},
        {pos: [4, 3, 3], state: "extendedae:assembler_matrix_wall{formed:true,powered:true}", nbt: {core: 0b, id: "extendedae:assembler_matrix_wall", proxy: {p: 0}, visual: {}}},
        {pos: [4, 3, 4], state: "extendedae:assembler_matrix_frame{formed:true,powered:true,shape:column_x}", nbt: {core: 0b, id: "extendedae:assembler_matrix_frame", proxy: {p: -1}, visual: {}}},
        {pos: [5, 3, 0], state: "extendedae:assembler_matrix_frame{formed:true,powered:true,shape:block}", nbt: {core: 0b, id: "extendedae:assembler_matrix_frame", proxy: {p: -1}, visual: {}}},
        {pos: [5, 3, 1], state: "extendedae:assembler_matrix_frame{formed:true,powered:true,shape:column_z}", nbt: {core: 0b, id: "extendedae:assembler_matrix_frame", proxy: {p: -1}, visual: {}}},
        {pos: [5, 3, 2], state: "extendedae:assembler_matrix_frame{formed:true,powered:true,shape:column_z}", nbt: {core: 0b, id: "extendedae:assembler_matrix_frame", proxy: {p: -1}, visual: {}}},
        {pos: [5, 3, 3], state: "extendedae:assembler_matrix_frame{formed:true,powered:true,shape:column_z}", nbt: {core: 0b, id: "extendedae:assembler_matrix_frame", proxy: {p: -1}, visual: {}}},
        {pos: [5, 3, 4], state: "extendedae:assembler_matrix_frame{formed:true,powered:true,shape:block}", nbt: {core: 0b, id: "extendedae:assembler_matrix_frame", proxy: {p: -1}, visual: {}}}
    ],
    entities: [],
    palette: [
        "extendedae:assembler_matrix_frame{formed:true,powered:true,shape:block}",
        "extendedae:assembler_matrix_frame{formed:true,powered:true,shape:column_z}",
        "extendedae:assembler_matrix_frame{formed:true,powered:true,shape:column_x}",
        "extendedae:assembler_matrix_wall{formed:true,powered:true}",
        "extendedae:assembler_matrix_frame{formed:true,powered:true,shape:column_y}",
        "extendedae:assembler_matrix_pattern{formed:true,powered:true}",
        "extendedae:assembler_matrix_speed{formed:true,powered:true}",
        "extendedae:assembler_matrix_crafter{formed:true,powered:true}"
    ]
}